Loading input data...
Generating data for partition_part 1
2022-06-30 15:59:05.520070: E external/org_tensorflow/tensorflow/compiler/xla/pjrt/pjrt_stream_executor_client.cc:2141] Execution of replica 0 failed: INTERNAL: Failed to load in-memory CUBIN: CUDA_ERROR_OUT_OF_MEMORY: out of memory
2022-06-30 15:59:06.977452: E external/org_tensorflow/tensorflow/compiler/xla/pjrt/pjrt_stream_executor_client.cc:2141] Execution of replica 0 failed: INTERNAL: Failed to load in-memory CUBIN: CUDA_ERROR_OUT_OF_MEMORY: out of memory
There is no trained parameters
2022-06-30 15:02:14.980649 Epoch  1 completed!
2022-06-30 15:08:16.900338 Epoch  2 completed!
2022-06-30 15:14:15.796133 Epoch  3 completed!
2022-06-30 15:20:13.893515 Epoch  4 completed!
2022-06-30 15:26:16.079039 Epoch  5 completed!
2022-06-30 15:32:20.255264 Epoch  6 completed!
2022-06-30 15:38:26.032733 Epoch  7 completed!
2022-06-30 15:44:29.531833 Epoch  8 completed!
2022-06-30 15:50:35.347885 Epoch  9 completed!
2022-06-30 15:56:44.451728 Epoch 10 completed!
The following exception occurs: INTERNAL: Failed to load in-memory CUBIN: CUDA_ERROR_OUT_OF_MEMORY: out of memory
Traceback (most recent call last):
  File "/root/Min/mathematics_conjectures/test_v3.py", line 239, in <module>
    train_accuracy, test_accuracy, combined_accuracy = print_accuracies(trained_params, test_dataset, train_dataset, batch_size)
  File "/root/Min/mathematics_conjectures/test_v3.py", line 71, in print_accuracies
    train_accuracy = compute_accuracies(
  File "/root/Min/mathematics_conjectures/test_v3.py", line 61, in compute_accuracies
    accs = model.accuracy(params_to_evaluate, b_features, b_rows_1, b_cols_1, b_rows_2, b_cols_2, b_ys,
  File "/root/anaconda3/envs/mpnn/lib/python3.9/site-packages/jax/_src/traceback_util.py", line 162, in reraise_with_filtered_traceback
    return fun(*args, **kwargs)
  File "/root/anaconda3/envs/mpnn/lib/python3.9/site-packages/jax/_src/api.py", line 473, in cache_miss
    out_flat = xla.xla_call(
  File "/root/anaconda3/envs/mpnn/lib/python3.9/site-packages/jax/core.py", line 1767, in bind
    return call_bind(self, fun, *args, **params)
  File "/root/anaconda3/envs/mpnn/lib/python3.9/site-packages/jax/core.py", line 1783, in call_bind
    outs = top_trace.process_call(primitive, fun_, tracers, params)
  File "/root/anaconda3/envs/mpnn/lib/python3.9/site-packages/jax/core.py", line 680, in process_call
    return primitive.impl(f, *tracers, **params)
  File "/root/anaconda3/envs/mpnn/lib/python3.9/site-packages/jax/_src/dispatch.py", line 185, in _xla_call_impl
    return compiled_fun(*args)
  File "/root/anaconda3/envs/mpnn/lib/python3.9/site-packages/jax/_src/dispatch.py", line 615, in _execute_compiled
    out_bufs_flat = compiled.execute(input_bufs_flat)
jax._src.traceback_util.UnfilteredStackTrace: jaxlib.xla_extension.XlaRuntimeError: INTERNAL: Failed to load in-memory CUBIN: CUDA_ERROR_OUT_OF_MEMORY: out of memory

The stack trace below excludes JAX-internal frames.
The preceding is the original exception that occurred, unmodified.

--------------------

The above exception was the direct cause of the following exception:

Traceback (most recent call last):
  File "/root/Min/mathematics_conjectures/test_v3.py", line 239, in <module>
    train_accuracy, test_accuracy, combined_accuracy = print_accuracies(trained_params, test_dataset, train_dataset, batch_size)
  File "/root/Min/mathematics_conjectures/test_v3.py", line 71, in print_accuracies
    train_accuracy = compute_accuracies(
  File "/root/Min/mathematics_conjectures/test_v3.py", line 61, in compute_accuracies
    accs = model.accuracy(params_to_evaluate, b_features, b_rows_1, b_cols_1, b_rows_2, b_cols_2, b_ys,
jaxlib.xla_extension.XlaRuntimeError: INTERNAL: Failed to load in-memory CUBIN: CUDA_ERROR_OUT_OF_MEMORY: out of memory
